Workbook

Sheet Student Master
F1: =SUBTOTAL(3,F3:F2096) -> 248 | I1: =COUNTIF(I3:I2089,"WIP") -> 73 | J1: =SUBTOTAL(3,J3:J2096) -> 248 | K1: =SUBTOTAL(9,K3:K2096) -> 217650 | L1: =SUBTOTAL(9,L3:L2096) -> 214050 | AA1: =SUBTOTAL(9,AA3:AA2096) -> 891800 | AB1: =SUBTOTAL(9,AB3:AB2096) -> 833700
A2: Revised Fee/Pending Fee | B2: 28-DEC-EXAM ? | C2: 28-DEC-EXAM ? | D2: # | E2: Student No | F2: Student Name | G2: Level # | H2: Student | I2: Level Progress | J2: Level Name | K2: Kit and Books Fee -Expected | L2: Kit and Books Fee -Received | M2: Kit and Books Fee -Received On | N2: Kits/Books Issued to Student On | O2: Level Joined On | P2: Batch | Q2: Level Completed on | R2: MONTHS TAken to complete levvel | S2: NO OF SESSIONS TAKEN | T2: Exam Planned Date | U2: Exam Actual Date | V2: Score | W2: Nominated for Trophy | X2: Trophy Season /Lot | Y2: Trophy Distributed | Z2: Fee Model | AA2: Expected Fee | AB2: Received Fee | AC2: Received Total Fee | AD2: Fee Received On | AE2: # Months if Monthly | AF2: Remark | AG2: GAPY/CASH?
D3: 1 | E3: A001 | F3: Aaditya Patil | G3: A01 | H3: =CONCATENATE(E3,"_",F3,"_",G3) -> A001_Aaditya Patil_A01 | I3: Completed | J3: Jr.KG | K3: 1650 | L3: 1650 | M3: 44841 | N3: 44841 | O3: 44841 | P3: O-M-F-3-4 | Q3: 44928 | R3: =(IF(Q3="",(TODAY()-O3),(Q3-O3)))/30 -> 2.9 | S3: =ROUNDUP(R3*8,0) -> 24 | Z3: 1st Free | AA3: 0 | AB3: 0 | AC3: NA | AD3: NA
D4: 2 | E4: A001 | F4: Aaditya Patil | G4: A03 | H4: =CONCATENATE(E4,"_",F4,"_",G4) -> A001_Aaditya Patil_A03 | I4: Completed | J4: Runner-1 | K4: 600 | L4: 600 | M4: 44929 | N4: 44929 | O4: 44929 | P4: O-M-F-3-4 | Q4: 45046 | R4: =(IF(Q4="",(TODAY()-O4),(Q4-O4)))/30 -> 3.9 | S4: =ROUNDUP(R4*8,0) -> 32 | Z4: Always Free | AA4: 0 | AB4: 0 | AC4: NA
D5: 3 | E5: A002 | F5: Tanush Thosare | G5: A01 | H5: =CONCATENATE(E5,"_",F5,"_",G5) -> A002_Tanush Thosare_A01 | I5: Completed | J5: Jr.KG | K5: 1600 | L5: 1600 | M5: 44841 | N5: 44841 | O5: 44841 | P5: O-M-F-3-4 | Q5: 44927 | R5: =(IF(Q5="",(TODAY()-O5),(Q5-O5)))/30 -> 2.8666667 | S5: =ROUNDUP(R5*8,0) -> 23 | Z5: 1st Special Fee | AA5: 2500 | AB5: 2500 | AC5: Yes | AD5: 44927
D6: 4 | E6: A002 | F6: Tanush Thosare | G6: A03 | H6: =CONCATENATE(E6,"_",F6,"_",G6) -> A002_Tanush Thosare_A03 | I6: Completed | J6: Runner-1 | K6: 600 | L6: 600 | M6: 44929 | N6: 44929 | O6: 44929 | P6: O-M-F-3-4 | Q6: 45040 | R6: =(IF(Q6="",(TODAY()-O6),(Q6-O6)))/30 -> 3.7 | S6: =ROUNDUP(R6*8,0) -> 30 | Z6: Level Wise | AA6: 3600 | AB6: 3600 | AC6: Yes | AD6: 45040
D7: 5 | E7: A003 | F7: Prathmesh Zope | G7: A08 | H7: =CONCATENATE(E7,"_",F7,"_",G7) -> A003_Prathmesh Zope_A08 | I7: Completed | J7: Sprinter Level-1 | K7: 1600 | L7: 1600 | M7: 44868 | N7: 44868 | O7: 44870 | P7: M-F-7-8 | Q7: 45034 | R7: =(IF(Q7="",(TODAY()-O7),(Q7-O7)))/30 -> 5.4666667 | S7: =ROUNDUP(R7*8,0) -> 44 | Z7: Level Wise | AA7: 3600 | AB7: 3600 | AC7: Yes | AD7: 44868
D8: 6 | E8: A003 | F8: Prathmesh Zope | G8: A09 | H8: =CONCATENATE(E8,"_",F8,"_",G8) -> A003_Prathmesh Zope_A09 | I8: Completed | J8: Sprinter Level-2 | K8: 400 | L8: 400 | M8: 45034 | N8: 45034 | O8: 45034 | P8: M-F-7-8 | Q8: 45121 | R8: =(IF(Q8="",(TODAY()-O8),(Q8-O8)))/30 -> 2.9 | S8: =ROUNDUP(R8*8,0) -> 24 | Z8: Level Wise | AA8: 3600 | AB8: 3600 | AC8: Yes | AD8: 45034
D9: 7 | E9: A003 | F9: Prathmesh Zope | G9: A10 | H9: =CONCATENATE(E9,"_",F9,"_",G9) -> A003_Prathmesh Zope_A10 | I9: Completed | J9: Sprinter Level-3 | K9: 400 | L9: 400 | M9: 45124 | N9: 45121 | O9: 45121 | P9: M-F-7-8 | Q9: 45268 | R9: =(IF(Q9="",(TODAY()-O9),(Q9-O9)))/30 -> 4.9 | S9: =ROUNDUP(R9*8,0) -> 40 | Z9: Level Wise | AA9: 3600 | AB9: 3600 | AC9: Yes | AD9: 45124
D10: 8 | E10: A003 | F10: Prathmesh Zope | G10: A11 | H10: =CONCATENATE(E10,"_",F10,"_",G10) -> A003_Prathmesh Zope_A11 | I10: Completed | J10: Sprinter Level-4 | K10: 400 | L10: 400 | M10: 45264 | N10: 45264 | O10: 45268 | P10: M-F-7-8 | Q10: 45437 | R10: =(IF(Q10="",(TODAY()-O10),(Q10-O10)))/30 -> 5.6333333 | S10: =ROUNDUP(R10*8,0) -> 46 | Z10: Level Wise | AA10: 3600 | AB10: 3600 | AC10: Yes | AD10: 45264
D11: 9 | E11: A003 | F11: Prathmesh Zope | G11: A12 | H11: =CONCATENATE(E11,"_",F11,"_",G11) -> A003_Prathmesh Zope_A12 | I11: Completed | J11: Advance Level-1 | K11: 400 | L11: 400 | M11: 45447 | N11: 45444 | O11: 45444 | P11: M-F-7-8 | Q11: 45629 | R11: =(IF(Q11="",(TODAY()-O11),(Q11-O11)))/30 -> 6.1666667 | S11: =ROUNDUP(R11*8,0) -> 50 | T11: 45629 | U11: 45629 | V11: 0.82 | W11: yes | X11: 2 | Y11: Yes | Z11: Level Wise | AA11: 3600 | AB11: 3600 | AC11: Yes | AD11: 45495
A12: Level Extension | B12: YES | D12: 10 | E12: A003 | F12: Prathmesh Zope | G12: A13 | H12: =CONCATENATE(E12,"_",F12,"_",G12) -> A003_Prathmesh Zope_A13 | I12: WIP | J12: Advance Level-2 | K12: 400 | M12: 45632 | N12: 45632 | O12: 45632 | P12: M-W-7-8 | R12: =(IF(Q12="",(TODAY()-O12),(Q12-O12)))/30 -> 11.8 | S12: =ROUNDUP(R12*8,0) -> 95 | Z12: Level Wise | AA12: 3600 | AB12: 3600 | AC12: Yes | AD12: 45686 | AE12: Gpay
D13: 11 | E13: A004 | F13: Asmi Kshirsagar | G13: A08 | H13: =CONCATENATE(E13,"_",F13,"_",G13) -> A004_Asmi Kshirsagar_A08 | I13: Completed | J13: Sprinter Level-1 | K13: 1600 | L13: 1600 | M13: 45263 | N13: 44868 | O13: 44870 | P13: M-F-7-8 | Q13: 45058 | R13: =(IF(Q13="",(TODAY()-O13),(Q13-O13)))/30 -> 6.2666667 | S13: =ROUNDUP(R13*8,0) -> 51 | Z13: Level Wise | AA13: 3600 | AB13: 3600 | AC13: Yes | AD13: 44935
D14: 12 | E14: A004 | F14: Asmi Kshirsagar | G14: A09 | H14: =CONCATENATE(E14,"_",F14,"_",G14) -> A004_Asmi Kshirsagar_A09 | I14: Completed | J14: Sprinter Level-2 | K14: 400 | L14: 400 | M14: 45058 | N14: 45058 | O14: 45058 | P14: M-F-7-8 | Q14: 45168 | R14: =(IF(Q14="",(TODAY()-O14),(Q14-O14)))/30 -> 3.6666667 | S14: =ROUNDUP(R14*8,0) -> 30 | Z14: Level Wise | AA14: 3600 | AB14: 3600 | AC14: Yes | AD14: 45058
D15: 13 | E15: A004 | F15: Asmi Kshirsagar | G15: A10 | H15: =CONCATENATE(E15,"_",F15,"_",G15) -> A004_Asmi Kshirsagar_A10 | I15: Completed | J15: Sprinter Level-3 | K15: 400 | L15: 400 | M15: 45186 | N15: 45186 | O15: 45180 | P15: M-F-7-8 | R15: =(IF(Q15="",(TODAY()-O15),(Q15-O15)))/30 -> 26.866667 | S15: =ROUNDUP(R15*8,0) -> 215 | T15: only exam pending | Z15: Level Wise | AA15: 3600 | AB15: 3600 | AC15: Yes | AD15: 45186
D16: 14 | E16: A005 | F16: Yatharth Kaushik | G16: V01 | H16: =CONCATENATE(E16,"_",F16,"_",G16) -> A005_Yatharth Kaushik_V01 | I16: Completed | J16: Vedic Level-1 | K16: 1600 | L16: 1600 | M16: 44897 | N16: 44897 | O16: 44889 | P16: T-T-6-7 | Q16: 44985 | R16: =(IF(Q16="",(TODAY()-O16),(Q16-O16)))/30 -> 3.2 | S16: =ROUNDUP(R16*8,0) -> 26 | Z16: Level Wise | AA16: 3600 | AB16: 3600 | AC16: Yes | AD16: 44985
D17: 15 | E17: A005 | F17: Yatharth Kaushik | G17: V02 | H17: =CONCATENATE(E17,"_",F17,"_",G17) -> A005_Yatharth Kaushik_V02 | I17: Completed | J17: Vedic Level-2 | K17: 600 | L17: 600 | M17: 45000 | N17: 44990 | O17: 44990 | P17: T-T-6-7 | Q17: 45076 | R17: =(IF(Q17="",(TODAY()-O17),(Q17-O17)))/30 -> 2.8666667 | S17: =ROUNDUP(R17*8,0) -> 23 | Z17: Level Wise | AA17: 3600 | AB17: 3600 | AC17: Yes | AD17: 45048
D18: 16 | E18: A006 | F18: Kushal Patil | G18: A03 | H18: =CONCATENATE(E18,"_",F18,"_",G18) -> A006_Kushal Patil_A03 | I18: Completed | J18: Runner-1 | K18: 1600 | L18: 1600 | M18: 44892 | N18: 44892 | O18: 44892 | P18: O-T-T-5-6 | Q18: 44969 | R18: =(IF(Q18="",(TODAY()-O18),(Q18-O18)))/30 -> 2.5666667 | S18: =ROUNDUP(R18*8,0) -> 21 | Z18: Level Wise | AA18: 3600 | AB18: 3600 | AC18: Yes | AD18: 44969
D19: 17 | E19: A006 | F19: Kushal Patil | G19: A04 | H19: =CONCATENATE(E19,"_",F19,"_",G19) -> A006_Kushal Patil_A04 | I19: Completed | J19: Runner-2 | K19: 600 | L19: 600 | M19: 45048 | N19: 45032 | O19: 45032 | P19: O-T-T-5-6 | Q19: 45137 | R19: =(IF(Q19="",(TODAY()-O19),(Q19-O19)))/30 -> 3.5 | S19: =ROUNDUP(R19*8,0) -> 28 | Z19: Level Wise | AA19: 3600 | AB19: 3600 | AC19: Yes | AD19: 45082
D20: 18 | E20: A006 | F20: Kushal Patil | G20: A05 | H20: =CONCATENATE(E20,"_",F20,"_",G20) -> A006_Kushal Patil_A05 | I20: Completed | J20: Runner-3 | K20: 600 | L20: 600 | M20: 45141 | N20: 45141 | O20: 45139 | P20: O-T-T-5-6 | Q20: 45229 | R20: =(IF(Q20="",(TODAY()-O20),(Q20-O20)))/30 -> 3 | S20: =ROUNDUP(R20*8,0) -> 24 | T20: Exam Pending | Z20: Level Wise | AA20: 3600 | AB20: 3600 | AC20: Yes | AD20: 45141
D21: 19 | E21: A007 | F21: Selene Kaur | G21: A03 | H21: =CONCATENATE(E21,"_",F21,"_",G21) -> A007_Selene Kaur_A03 | I21: Completed | J21: Runner-1 | K21: 1600 | L21: 1600 | M21: 44957 | N21: 44960 | O21: 44960 | P21: M-F-5-6 | Q21: 45078 | R21: =(IF(Q21="",(TODAY()-O21),(Q21-O21)))/30 -> 3.9333333 | S21: =ROUNDUP(R21*8,0) -> 32 | Z21: Level Wise | AA21: 3600 | AB21: 3600 | AC21: Yes | AD21: 45078
D22: 20 | E22: A007 | F22: Selene Kaur | G22: A04 | H22: =CONCATENATE(E22,"_",F22,"_",G22) -> A007_Selene Kaur_A04 | I22: Completed | J22: Runner-2 | K22: 400 | L22: 400 | M22: 45140 | N22: 45135 | O22: 45135 | P22: M-F-5-6 | Q22: 45204 | R22: =(IF(Q22="",(TODAY()-O22),(Q22-O22)))/30 -> 2.3 | S22: =ROUNDUP(R22*8,0) -> 19 | Z22: Level Wise | AA22: 3600 | AB22: 3600 | AC22: Yes | AD22: 45204
D23: 21 | E23: A007 | F23: Selene Kaur | G23: A05 | H23: =CONCATENATE(E23,"_",F23,"_",G23) -> A007_Selene Kaur_A05 | I23: Completed | J23: Runner-3 | K23: 400 | L23: 400 | M23: 45263 | N23: 45263 | O23: 45266 | P23: M-F-5-6 | Q23: 45412 | R23: =(IF(Q23="",(TODAY()-O23),(Q23-O23)))/30 -> 4.8666667 | S23: =ROUNDUP(R23*8,0) -> 39 | T23: Exam Pending | Z23: Level Wise | AA23: 3600 | AB23: 3600 | AC23: Yes | AD23: 45330
D24: 22 | E24: A008 | F24: Dighvi Nikumbh | G24: A01 | H24: =CONCATENATE(E24,"_",F24,"_",G24) -> A008_Dighvi Nikumbh_A01 | I24: Completed | J24: Jr.KG | K24: 1600 | L24: 1600 | M24: 44970 | N24: 44960 | O24: 44960 | P24: M-F-5-6 | Q24: 45046 | R24: =(IF(Q24="",(TODAY()-O24),(Q24-O24)))/30 -> 2.8666667 | S24: =ROUNDUP(R24*8,0) -> 23 | Z24: Level Wise | AA24: 3000 | AB24: 3000 | AC24: Yes | AD24: 45067
D25: 23 | E25: A008 | F25: Dighvi Nikumbh | G25: A02 | H25: =CONCATENATE(E25,"_",F25,"_",G25) -> A008_Dighvi Nikumbh_A02 | I25: Completed | J25: Sr.KG | K25: 400 | L25: 400 | M25: 45058 | N25: 45055 | O25: 45055 | P25: M-F-5-6 | Q25: 45150 | R25: =(IF(Q25="",(TODAY()-O25),(Q25-O25)))/30 -> 3.1666667 | S25: =ROUNDUP(R25*8,0) -> 26 | Z25: Level Wise | AA25: 3000 | AB25: 3000 | AC25: Yes | AD25: 45150
D26: 24 | E26: A008 | F26: Dighvi Nikumbh | G26: A03 | H26: =CONCATENATE(E26,"_",F26,"_",G26) -> A008_Dighvi Nikumbh_A03 | I26: Completed | J26: Runner-1 | K26: 400 | L26: 400 | M26: 45152 | N26: 45152 | O26: 45152 | P26: M-F-7-8 | Q26: 45534 | R26: =(IF(Q26="",(TODAY()-O26),(Q26-O26)))/30 -> 12.733333 | S26: =ROUNDUP(R26*8,0) -> 102 | V26: 0.91 | Z26: Level Wise | AA26: 3600 | AB26: 3600 | AC26: Yes | AD26: 45250
D27: 25 | E27: A009 | F27: Saiansh Kumar | G27: A03 | H27: =CONCATENATE(E27,"_",F27,"_",G27) -> A009_Saiansh Kumar_A03 | I27: Completed | J27: Runner-1 | K27: 1600 | L27: 1600 | M27: 45003 | N27: 45002 | O27: 45002 | P27: M-F-5-6 | Q27: 45219 | R27: =(IF(Q27="",(TODAY()-O27),(Q27-O27)))/30 -> 7.2333333 | S27: =ROUNDUP(R27*8,0) -> 58 | Z27: Level Wise | AA27: 3600 | AB27: 3600 | AC27: Yes | AD27: 45110
D28: 26 | E28: A009 | F28: Saiansh Kumar | G28: A04 | H28: =CONCATENATE(E28,"_",F28,"_",G28) -> A009_Saiansh Kumar_A04 | I28: Completed | J28: Runner-2 | K28: 400 | L28: 400 | M28: 45221 | N28: 13-Oct023 | O28: 45212 | P28: M-F-5-6 | Q28: 45350 | R28: =(IF(Q28="",(TODAY()-O28),(Q28-O28)))/30 -> 4.6 | S28: =ROUNDUP(R28*8,0) -> 37 | Z28: Level Wise | AA28: 3600 | AB28: 3600 | AC28: Yes | AD28: 45327
D29: 27 | E29: A010 | F29: Atharva Titave | G29: A02 | H29: =CONCATENATE(E29,"_",F29,"_",G29) -> A010_Atharva Titave_A02 | I29: Completed | J29: Sr.KG | K29: 1600 | L29: 1600 | M29: 45021 | N29: 45021 | O29: 45018 | P29: SAT-4-6 | Q29: 45122 | R29: =(IF(Q29="",(TODAY()-O29),(Q29-O29)))/30 -> 3.4666667 | S29: =ROUNDUP(R29*8,0) -> 28 | Z29: Level Wise | AA29: 3600 | AB29: 3600 | AC29: Yes | AD29: 45066
D30: 28 | E30: A010 | F30: Atharva Titave | G30: A03 | H30: =CONCATENATE(E30,"_",F30,"_",G30) -> A010_Atharva Titave_A03 | I30: Completed | J30: Runner-1 | K30: 400 | L30: 400 | M30: 45123 | N30: 45123 | O30: 45121 | P30: SAT-4-6 | Q30: 45342 | R30: =(IF(Q30="",(TODAY()-O30),(Q30-O30)))/30 -> 7.3666667 | S30: =ROUNDUP(R30*8,0) -> 59 | Z30: Level Wise | AA30: 3600 | AB30: 3600 | AC30: Yes | AD30: 45199
D31: 29 | E31: A010 | F31: Atharva Titave | G31: A04 | H31: =CONCATENATE(E31,"_",F31,"_",G31) -> A010_Atharva Titave_A04 | I31: Completed | J31: Runner-2 | K31: 400 | L31: 400 | M31: 45352 | N31: 45352 | O31: 45360 | P31: SAT-4-6 | Q31: 45501 | R31: =(IF(Q31="",(TODAY()-O31),(Q31-O31)))/30 -> 4.7 | S31: =ROUNDUP(R31*8,0) -> 38 | T31: 45493 | U31: 45501 | V31: 0.83 | Z31: Level Wise | AA31: 3600 | AB31: 3600 | AC31: Yes | AD31: 45442 | AE31: 5
D32: 30 | E32: A010 | F32: Atharva Titave | G32: A05 | H32: =CONCATENATE(E32,"_",F32,"_",G32) -> A010_Atharva Titave_A05 | I32: Completed | J32: Runner-3 | K32: 400 | L32: 400 | M32: 45553 | N32: 45501 | O32: 45501 | P32: SAT-4-6 | Q32: 45724 | R32: =(IF(Q32="",(TODAY()-O32),(Q32-O32)))/30 -> 7.4333333 | S32: =ROUNDUP(R32*8,0) -> 60 | T32: 45724 | U32: 45724 | V32: 0.95 | W32: Yes | Y32: Yes | Z32: Level Wise | AA32: 3600 | AB32: 3600 | AC32: yes | AD32: 45553
A33: Level Fee & Extension | B33: YES | D33: 31 | E33: A010 | F33: Atharva Titave | G33: A06 | H33: =CONCATENATE(E33,"_",F33,"_",G33) -> A010_Atharva Titave_A06 | I33: WIP | J33: Runner-4 | K33: 400 | L33: 400 | M33: 45729 | N33: 45752 | O33: 45752 | P33: SAT-4-6 | Z33: Level Wise | AA33: 3600
D34: 32 | E34: A011 | F34: Shresth Deb | G34: A03 | H34: =CONCATENATE(E34,"_",F34,"_",G34) -> A011_Shresth Deb_A03 | I34: Completed | J34: Runner-1 | K34: 1600 | L34: 1600 | M34: 45020 | N34: 45020 | O34: 45020 | P34: M-F-7-8 | Q34: 45128 | R34: =(IF(Q34="",(TODAY()-O34),(Q34-O34)))/30 -> 3.6 | S34: =ROUNDUP(R34*8,0) -> 29 | Z34: Monthly | AA34: 4800 | AB34: 4800 | AC34: Yes | AD34: 45113
D35: 33 | E35: A011 | F35: Shresth Deb | G35: A04 | H35: =CONCATENATE(E35,"_",F35,"_",G35) -> A011_Shresth Deb_A04 | I35: Completed | J35: Runner-2 | K35: 400 | L35: 400 | M35: 45135 | N35: 45135 | O35: 45124 | P35: M-F-7-8 | Q35: 45200 | R35: =(IF(Q35="",(TODAY()-O35),(Q35-O35)))/30 -> 2.5333333 | S35: =ROUNDUP(R35*8,0) -> 21 | Z35: Monthly | AA35: 3600 | AB35: 3600 | AC35: Yes | AD35: 45201
D36: 34 | E36: A011 | F36: Shresth Deb | G36: A05 | H36: =CONCATENATE(E36,"_",F36,"_",G36) -> A011_Shresth Deb_A05 | I36: Completed | J36: Runner-3 | K36: 400 | L36: 400 | M36: 45208 | N36: 45205 | O36: 45205 | P36: M-F-7-8 | Q36: 45327 | R36: =(IF(Q36="",(TODAY()-O36),(Q36-O36)))/30 -> 4.0666667 | S36: =ROUNDUP(R36*8,0) -> 33 | Z36: Monthly | AA36: 4800 | AB36: 4800 | AC36: Yes | AD36: 45327
D37: 35 | E37: A011 | F37: Shresth Deb | G37: A06 | H37: =CONCATENATE(E37,"_",F37,"_",G37) -> A011_Shresth Deb_A06 | I37: Completed | J37: Runner-4 | K37: 400 | L37: 400 | M37: 45362 | N37: 45352 | O37: 45352 | P37: M-F-7-8 | Q37: 45831 | R37: =(IF(Q37="",(TODAY()-O37),(Q37-O37)))/30 -> 15.966667 | S37: =ROUNDUP(R37*8,0) -> 128 | Z37: Monthly | AA37: 5400 | AB37: 5400 | AC37: NO | AD37: 45478 | AE37: 5
B38: NO | D38: 36 | E38: A011 | F38: Shresth Deb | G38: A07 | H38: =CONCATENATE(E38,"_",F38,"_",G38) -> A011_Shresth Deb_A07 | I38: WIP | J38: Runner 5 | K38: 400 | L38: 400 | M38: 45831 | N38: 45831 | O38: 45831 | Z38: Monthly | AA38: 3600 | AB38: 4800 | AC38: No | AD38: 45933 | AE38: 4 | AF38: gpay
D39: 37 | E39: A012 | F39: Swara Patil | G39: A02 | H39: =CONCATENATE(E39,"_",F39,"_",G39) -> A012_Swara Patil_A02 | I39: Completed | J39: Sr.KG | K39: 1600 | L39: 1600 | M39: 45026 | N39: 45026 | O39: 45026 | P39: SAT-4-6 | Q39: 45073 | R39: =(IF(Q39="",(TODAY()-O39),(Q39-O39)))/30 -> 1.5666667 | S39: =ROUNDUP(R39*8,0) -> 13 | Z39: Level Wise | AA39: 3600 | AB39: 3600 | AC39: Yes | AD39: 45073
D40: 38 | E40: A012 | F40: Swara Patil | G40: A03 | H40: =CONCATENATE(E40,"_",F40,"_",G40) -> A012_Swara Patil_A03 | I40: WIP_InActive | J40: Runner-1 | K40: 400 | L40: 400 | M40: 45152 | N40: 45152 | O40: 45152 | P40: SAT-4-6 | R40: =(IF(Q40="",(TODAY()-O40),(Q40-O40)))/30 -> 27.8 | S40: =ROUNDUP(R40*8,0) -> 223 | Z40: Level Wise | AA40: 3600 | AB40: 3600 | AC40: Yes | AD40: 45152
...

Sheet 28-Dec-COMPETITION STUDENTS
B2: # | C2: Student No | D2: Student Name | E2: Level # | F2: Current Level | G2: Level Joined On
B3: 1 | C3: A098 | D3: Agastya Dhanvijay Patil | E3: A01 | F3: Jr.KG
B4: 1 | C4: A099 | D4: Ashwath Dhanvijay Patil | E4: A01 | F4: Jr.KG
B5: 1 | C5: A114 | D5: Aarya Pawar Chaudhary | E5: A01 | F5: Jr.KG | G5: 45895
B6: 2 | C6: A044 | D6: Paridhi Agarwal | E6: A02 | F6: Jr.KG | G6: 45637
B7: 2 | C7: A093 | D7: Hrisha Reddy | E7: A02 | F7: Jr.KG | G7: 45818
B8: 2 | C8: A104 | D8: Maiesha Anand | E8: A02 | F8: Jr.KG | G8: 45840
B9: 2 | C9: A108 | D9: Raashi Rajnale | E9: A02 | F9: Jr.KG | G9: 45844
B10: 2 | C10: A117 | D10: Aarav Jagdish Patil | E10: A02 | F10: Sr.KG | G10: 45908
B11: 2 | C11: A118 | D11: Kriyansh Chhabria | E11: A02 | F11: Jr.KG | G11: 45928
B12: 2 | C12: A119 | D12: Maneet Manoj Muttepawar | E12: A02 | F12: Jr.KG | G12: 45941
B13: 3 | C13: A056 | D13: Hridhaan Bagla | E13: A03 | F13: SR.KG | G13: 45739
B14: 3 | C14: A066 | D14: Hitansh Agarwal | E14: A03 | F14: Sr.KG | G14: 45815
B15: 3 | C15: A067 | D15: Hitanshi Agarwal | E15: A03 | F15: Sr.KG | G15: 45815
B16: 3 | C16: A071 | D16: Manan Mulchandani | E16: A03 | F16: Jr.KG | G16: 45906
... B27: 4 | C27: A092 | D27: Pranvi Reddy | E27: A04 | F27: Sprinter Level-1 | G27: 45818
B28: 4 | C28: A120 | D28: DHRUVA SINGHAL | F28: Runner 2
B29: 5 | C29: A062 | D29: Kabeer Kherajani | E29: A05 | F29: Runner 3 | G29: 45859
B30: 5 | C30: A074 | D30: Vedika Shinde | E30: A05 | F30: Runner 3 | G30: 45868
B31: 5 | C31: A075 | D31: Yuvan Lalchandani | E31: A05 | F31: Runner 3
B32: 5 | C32: A089 | D32: Heer Sharma | E32: A09 | F32: Sprinter Level-2 | G32: 45895
B33: 6 | C33: A010 | D33: Atharva Titave | E33: A06 | F33: Runner-4 | G33: 45752
B34: 6 | C34: A024 | D34: Shreshth Gupta | E34: A05 | F34: Runner-4 | G34: 45945
B35: 6 | C35: A034 | D35: Shreya Asarma | E35: A06 | F35: Runner-4 | G35: 45811
B36: 6 | C36: A064 | D36: Samyak Bora | E36: A06 | F36: Runner-4 | G36: 45871
B37: 6 | C37: A088 | D37: Aarav Sandeep Dhanajkar | E37: A10 | F37: Sprinter Level-3
B38: 7 | C38: 0-bOSS | D38: Arnav Patil | E38: A13 | F38: Advance Level-2
B39: 7 | C39: A003 | D39: Prathmesh Zope | E39: A13 | F39: Advance Level-2 | G39: 45632

Sheet Sheet1
D3: Here’s your data organized in a clean spreadsheet-style format with columns for easy tracking:
D4: 🗂️ Student Fee Tracker | I4: =SUM(I6:I70) -> 99000
D5: Student Name | E5: Level Type | F5: Start Date | G5: Fee Paid / Received | H5: Pending Items / Notes | I5: Total Amount (₹)
D6: Prathmesh | E6: Advance | F6: 46015 | G6: — | H6: Level Extension Oct'25 | I6: 1600
D7: Riyansh Pawar | E7: Advance Level 2 | F7: 45816 | G7: ₹3600 + ₹1600 | H7: — | I7: 5200
D8: Shresth Deb | E8: Runner 5 | F8: 45833 | G8: Till Sep | H8: Oct advance awaited | I8: —
D9: Shreshth Gupta | E9: Runner 4 | F9: — | G9: — | H9: Awaiting confirmation; trophy request denied | I9: —
D10: Chaitnya Bhave | E10: Runner 3 | F10: 45884 | G10: — | H10: Aug–Sep ₹1200 + Sep–Oct ₹1400 | I10: 2600
D11: Aayushman Kale | E11: Runner 5 | F11: 45712 | G11: ₹3600 + ₹1600 | H11: — | I11: 5200
D12: Jyotiraditya Jagtap | E12: Runner 5 | F12: 45712 | G12: ₹3600 + ₹1600 | H12: — | I12: 5200
D13: Vikramaditya Jagtap | E13: Runner 4 | F13: 45712 | G13: ₹3600 + ₹1600 | H13: — | I13: 5200
D14: Shreya Asarma | E14: Runner 4 | F14: 45811 | G14: — | H14: Level Extension Oct'25 | I14: 1600
D15: Spruha Patil | E15: Runner 2 | F15: 45579 | G15: — | H15: ₹1800 balance + Oct'25 extension; check progress | I15: 3400
D16: Aaradhya | E16: Sprinter 3 | F16: 45812 | G16: ₹3600 + ₹1600 | H16: — | I16: 5200
D17: Paridhi Agarwal | E17: — | F17: — | G17: Mar'25 pending | H17: Sep ₹1200 + Oct ₹1600 | I17: 2800
D18: Shridnyesh Aher | E18: Runner 2 | F18: — | G18: Jul'25 pending | H18: Sep ₹1200 + Oct ₹1600 + books ₹400 | I18: 3200
D19: Arnish Jamtani | E19: Runner 3 | F19: 45812 | G19: — | H19: Level Extension Oct'25 awaited | I19: 1600
D20: Vedant Kumar | E20: Sprinter 2 | F20: 45941 | G20: — | H20: Sep ₹1200 + Oct ₹1600 + books ₹400 | I20: 3200
D21: Mahir Gandhi | E21: Runner 3 | F21: 45691 | G21: 3 months paid till July | H21: Sep ₹1200 + Oct ₹1600 + books ₹400 | I21: 3200
D22: Vivaan Garg | E22: — | F22: — | G22: — | H22: Neha to update | I22: —
D23: Yugansh Pawar | E23: Runner 1 | F23: 45693 | G23: — | H23: ₹3600 + ₹1600 pending | I23: 5200
D24: Hridhaan Bagla | E24: Runner 1 | F24: 45739 | G24: Till 21-Jul | H24: Aug–Sep ₹2400 + Oct ₹1600 | I24: 4000
D25: Advik Kahdelval | E25: — | F25: — | G25: — | H25: Aug ₹1200 + Oct ₹1600 pending; check with Neha | I25: 2800
D26: Kaira Sharma | E26: Runner 1 | F26: 45627 | G26: Till Apr | H26: May–Oct pending; Neha to confirm | I26: —
D27: Kabir Kherajani | E27: Runner 3 | F27: 45859 | G27: — | H27: Jul–Sep ₹3600 + Oct ₹1600 | I27: 5200
D28: Samyak | E28: Runner 4 | F28: 45871 | G28: — | H28: ₹3600 + books ₹400 | I28: 4000
D29: Hitanshi | E29: — | F29: 45780 | G29: — | H29: Books + monthly fee pending; Neha to update | I29: —
D30: Shourya | E30: — | F30: — | G30: — | H30: Neha to update | I30: —
D31: Manan Mulchandani | E31: Sr KG | F31: 45823 | G31: — | H31: ₹2000 balance + Oct'25 extension | I31: 3600
D32: Hazel Lalvani | E32: Runner 2 | F32: 45589 | G32: — | H32: Aug–Sep ₹1200 + Oct ₹1600 | I32: 2800
D33: Vedika | E33: Runner 3 | F33: 45868 | G33: — | H33: Level fee pending | I33: 3600
D34: Yuvan Lalchandani | E34: Runner 2 & 3 | F34: — | G34: — | H34: ₹3600 + ₹3600 + books ₹400 | I34: 7600
D35: Bhavya | E35: Runner 2 | F35: 45907 | G35: — | H35: ₹3600 + books ₹400 | I35: 4000
D36: Mayank Agarwal | E36: Sprinter 1 | F36: — | G36: — | H36: Level Extension Oct'25 | I36: 1600
D37: Aarav Gadsingh | E37: Runner 1 | F37: 45750 | G37: — | H37: Half level fee pending | I37: 1800
D38: Hiya Agarwal | E38: Runner 2 | F38: — | G38: — | H38: Level fee pending | I38: 3600
D39: Let me know if you'd like this exported into a table you can copy into Excel or Google Sheets!

Sheet Level Details
C2: # | D2: Level Name | E2: ## | G2: Jr.KG | H2: Sr.KG | I2: Runner-1 | J2: Runner-2 | K2: Runner-3 | L2: Runner-4 | M2: Sprinter Level-1 | N2: Sprinter Level-2 | O2: Sprinter Level-3 | P2: Sprinter Level-4 | Q2: Advance Level-1 | R2: Vedic Level-1 | S2: Vedic Level-2 | T2: Grand Total
C3: A01 | D3: Jr.KG | E3: A01 | G3: 5 | H3: 7 | I3: 24 | J3: 13 | K3: 6 | L3: 2 | M3: 8 | N3: 3 | O3: 2 | P3: 1 | Q3: 1 | R3: 2 | S3: 1 | T3: 75
C4: A02 | D4: Sr.KG | E4: A02
C5: A03 | D5: Runner-1 | E5: A03
C6: A04 | D6: Runner-2 | E6: A04
C7: A05 | D7: Runner-3 | E7: A05
C8: A06 | D8: Runner-4 | E8: A06
C9: A07 | D9: Runner-5 | E9: A07
C10: A08 | D10: Sprinter Level-1 | E10: A08
C11: A09 | D11: Sprinter Level-2 | E11: A09
C12: A10 | D12: Sprinter Level-3 | E12: A10
C13: A11 | D13: Sprinter Level-4 | E13: A11
C14: A12 | D14: Advance Level-1 | E14: A12
C15: A13 | D15: Advance Level-2 | E15: A13
... C20: V03 | D20: Vedic Level-3 | E20: V03

Sheet S0
B2: Sr.No | C2: Student Name | D2: Academy Joined ON | E2: Fees Paid TILL Date | F2: Admission Form Filled? | G2: # Level Completed | H2: Current Status | I2: Sr.No
B3: A001 | C3: Aaditya Patil | D3: 44841 | E3: 0 | F3: Yes | G3: 2 | H3: Inactive | I3: A001
B4: A002 | C4: Tanush Thosare | D4: 44841 | E4: 6100 | F4: Yes | G4: 2 | H4: Inactive | I4: A002
B5: A003 | C5: Prathmesh Zope | D5: 44870 | E5: 14400 | F5: Yes | G5: 4 | H5: Active | I5: A003
B6: A004 | C6: Asmi Kshirsagar | D6: 44870 | E6: 10800 | F6: Yes | G6: 3 | H6: Inactive | I6: A004
B7: A005 | C7: Yatharth Kaushik | D7: 44889 | E7: 7200 | F7: Yes | G7: 2 | H7: Inactive | I7: A005
B8: A006 | C8: Kushal Patil | D8: 44892 | E8: 10800 | F8: Yes | G8: 3 | H8: Inactive | I8: A006
B9: A007 | C9: Selene Kaur | D9: 44960 | E9: 10800 | F9: Yes | G9: 2 | H9: Active | I9: A007
B10: A008 | C10: Dighvi Nikumbh | D10: 44960 | E10: 9600 | F10: Yes | G10: 2 | H10: Active | I10: A008
B11: A009 | C11: Saiansh Kumar | D11: 45002 | E11: 7200 | F11: Yes | G11: 2 | H11: Inactive | I11: A009
B12: A010 | C12: Atharva Titave | D12: 45018 | E12: 10800 | F12: Yes | G12: 2 | H12: Active | I12: A010
B13: A011 | C13: Shresth Deb | D13: 45020 | E13: 17400 | F13: Yes | G13: 3 | H13: Active | I13: A011
B14: A012 | C14: Swara Patil | D14: 45026 | E14: 7200 | F14: Yes | G14: 1 | H14: Active | I14: A012
... B41: A039 | C41: Prisha Shah | D41: 45456 | E41: 1000 | F41: Yes | G41: 0 | H41: Active | I41: A039

Sheet S1
A3: Count of Level Progress | B3: Column Labels
A4: Student | B4: Jr.KG | C4: Sr.KG | D4: Runner-1 | E4: Runner-2 | F4: Runner-3 | G4: Runner-4 | H4: Sprinter Level-1 | I4: Sprinter Level-2 | J4: Sprinter Level-3 | K4: Sprinter Level-4 | L4: Advance Level-1 | M4: Vedic Level-1 | N4: Vedic Level-2 | O4: Grand Total | P4: Status
A5: Prathmesh Zope | H5: 1 | I5: 1 | J5: 1 | K5: 1 | L5: 1 | O5: 5 | P5: =VLOOKUP(A5,S0!C:H,6,0) -> Active
A6: Aarohi Fegde | D6: 1 | E6: 1 | F6: 1 | G6: 1 | O6: 4 | P6: =VLOOKUP(A6,S0!C:H,6,0) -> Active
A7: Shresth Deb | D7: 1 | E7: 1 | F7: 1 | G7: 1 | O7: 4 | P7: =VLOOKUP(A7,S0!C:H,6,0) -> Active
A8: Ishan Prasad | D8: 1 | E8: 1 | F8: 1 | O8: 3 | P8: =VLOOKUP(A8,S0!C:H,6,0) -> Active
A9: Asmi Kshirsagar | H9: 1 | I9: 1 | J9: 1 | O9: 3 | P9: =VLOOKUP(A9,S0!C:H,6,0) -> Inactive
A10: Riyansh Pawar | D10: 1 | E10: 1 | F10: 1 | O10: 3 | P10: =VLOOKUP(A10,S0!C:H,6,0) -> Active
A11: Selene Kaur | D11: 1 | E11: 1 | F11: 1 | O11: 3 | P11: =VLOOKUP(A11,S0!C:H,6,0) -> Active
A12: Dighvi Nikumbh | B12: 1 | C12: 1 | D12: 1 | O12: 3 | P12: =VLOOKUP(A12,S0!C:H,6,0) -> Active
A13: Atharva Titave | C13: 1 | D13: 1 | E13: 1 | O13: 3 | P13: =VLOOKUP(A13,S0!C:H,6,0) -> Active
A14: Kushal Patil | D14: 1 | E14: 1 | F14: 1 | O14: 3 | P14: =VLOOKUP(A14,S0!C:H,6,0) -> Inactive
A15: Shubhra Rokade | H15: 1 | I15: 1 | O15: 2 | P15: =VLOOKUP(A15,S0!C:H,6,0) -> Active
A16: Vikramaditya Jagtap | D16: 1 | E16: 1 | O16: 2 | P16: =VLOOKUP(A16,S0!C:H,6,0) -> Active
A17: Swastika Yadhav | D17: 1 | E17: 1 | O17: 2 | P17: =VLOOKUP(A17,S0!C:H,6,0) -> Active
A18: Yatharth Kaushik | M18: 1 | N18: 1 | O18: 2 | P18: =VLOOKUP(A18,S0!C:H,6,0) -> Inactive
A19: Jyotiraditya Jagtap | D19: 1 | E19: 1 | O19: 2 | P19: =VLOOKUP(A19,S0!C:H,6,0) -> Active
A20: Aayushman Kale | D20: 1 | E20: 1 | O20: 2 | P20: =VLOOKUP(A20,S0!C:H,6,0) -> Active
A21: Swara Patil | C21: 1 | D21: 1 | O21: 2 | P21: =VLOOKUP(A21,S0!C:H,6,0) -> Active
A22: Saiansh Kumar | D22: 1 | E22: 1 | O22: 2 | P22: =VLOOKUP(A22,S0!C:H,6,0) -> Inactive
A23: Tanush Thosare | B23: 1 | D23: 1 | O23: 2 | P23: =VLOOKUP(A23,S0!C:H,6,0) -> Inactive
A24: Abhay Patil | D24: 1 | E24: 1 | O24: 2 | P24: =VLOOKUP(A24,S0!C:H,6,0) -> Active
A25: Shreshth Gupta | C25: 1 | D25: 1 | O25: 2 | P25: =VLOOKUP(A25,S0!C:H,6,0) -> Active
A26: Aaditya Patil | B26: 1 | D26: 1 | O26: 2 | P26: =VLOOKUP(A26,S0!C:H,6,0) -> Inactive
A27: Yashwi Patil | C27: 1 | O27: 1 | P27: =VLOOKUP(A27,S0!C:H,6,0) -> Active
A28: Ira Deshmukh | H28: 1 | O28: 1 | P28: =VLOOKUP(A28,S0!C:H,6,0) -> Active
A29: Spruha Patil | D29: 1 | O29: 1 | P29: =VLOOKUP(A29,S0!C:H,6,0) -> Active
A30: Riyanshi Varma | H30: 1 | O30: 1 | P30: =VLOOKUP(A30,S0!C:H,6,0) -> Inactive
A31: Prisha Shah | C31: 1 | O31: 1 | P31: =VLOOKUP(A31,S0!C:H,6,0) -> Active
A32: Dhruv Bawankar | D32: 1 | O32: 1 | P32: =VLOOKUP(A32,S0!C:H,6,0) -> Active
A33: Nurvi Parad | B33: 1 | O33: 1 | P33: =VLOOKUP(A33,S0!C:H,6,0) -> Active
A34: Kaivalya Patil | D34: 1 | O34: 1 | P34: =VLOOKUP(A34,S0!C:H,6,0) -> Inactive
A35: Swara Kondhare | H35: 1 | O35: 1 | P35: =VLOOKUP(A35,S0!C:H,6,0) -> Active
A36: Shlesh Nemade | M36: 1 | O36: 1 | P36: =VLOOKUP(A36,S0!C:H,6,0) -> Inactive
A37: Aara Y | H37: 1 | O37: 1 | P37: =VLOOKUP(A37,S0!C:H,6,0) -> Active
A38: Aaradhya | H38: 1 | O38: 1 | P38: =VLOOKUP(A38,S0!C:H,6,0) -> Active
A39: Riyansh Dalvi | B39: 1 | O39: 1 | P39: =VLOOKUP(A39,S0!C:H,6,0) -> Inactive
A40: Nihir Galani | D40: 1 | O40: 1 | P40: =VLOOKUP(A40,S0!C:H,6,0) -> Inactive
A41: Chaitnya Bhave | D41: 1 | O41: 1 | P41: =VLOOKUP(A41,S0!C:H,6,0) -> Active
A42: Shreya Asarma | D42: 1 | O42: 1 | P42: =VLOOKUP(A42,S0!C:H,6,0) -> Active
...

Sheet WIP-D
F2: =TODAY() -> 45986
A3: Level Progress | B3: WIP | C3: =C40 -> 0
K4: =SUM(K6:K800) -> 36900
A5: Student Name | B5: Count of Student Name | C5: Sum of Received Fee | D5: Level Start Date | E5: Batch | F5: Fee Model | G5: Months by formula | H5: Actual Months running | I5: Focus Priority | J5: Remark | K5: Expected Payment for Month
A6: Aaradhya | B6: 1 | D6: =VLOOKUP(A6,'Student Master'!H:AB,8,0) -> #N/A | E6: =VLOOKUP(A6,'Student Master'!H:AB,9,0) -> #N/A | F6: =VLOOKUP(A6,'Student Master'!H:AB,17,0) -> #N/A | G6: =$F$2-D6 -> #N/A | H6: 6 | K6: 0
A7: Aarav Gadsingh | B7: 1 | D7: =VLOOKUP(A7,'Student Master'!H:AB,8,0) -> #N/A | E7: =VLOOKUP(A7,'Student Master'!H:AB,9,0) -> #N/A | F7: =VLOOKUP(A7,'Student Master'!H:AB,17,0) -> #N/A | G7: =$F$2-D7 -> #N/A | H7: 6 | K7: 0
A8: Aayushman Kale | B8: 1 | D8: =VLOOKUP(A8,'Student Master'!H:AB,8,0) -> #N/A | E8: =VLOOKUP(A8,'Student Master'!H:AB,9,0) -> #N/A | F8: =VLOOKUP(A8,'Student Master'!H:AB,17,0) -> #N/A | G8: =$F$2-D8 -> #N/A | H8: 6 | K8: 0
A9: Abhay Patil | B9: 1 | C9: 4000 | D9: =VLOOKUP(A9,'Student Master'!H:AB,8,0) -> #N/A | E9: =VLOOKUP(A9,'Student Master'!H:AB,9,0) -> #N/A | F9: =VLOOKUP(A9,'Student Master'!H:AB,17,0) -> #N/A | G9: =$F$2-D9 -> #N/A | H9: 6 | K9: 0
A10: Arnav Pol | B10: 1 | C10: 1200 | D10: =VLOOKUP(A10,'Student Master'!H:AB,8,0) -> #N/A | E10: =VLOOKUP(A10,'Student Master'!H:AB,9,0) -> #N/A | F10: =VLOOKUP(A10,'Student Master'!H:AB,17,0) -> #N/A | G10: =$F$2-D10 -> #N/A | H10: 6 | K10: 0
A11: Arnish Jhamtani | B11: 1 | C11: 3600 | D11: =VLOOKUP(A11,'Student Master'!H:AB,8,0) -> #N/A | E11: =VLOOKUP(A11,'Student Master'!H:AB,9,0) -> #N/A | F11: =VLOOKUP(A11,'Student Master'!H:AB,17,0) -> #N/A | G11: =$F$2-D11 -> #N/A | H11: 6 | K11: 0
A12: Atharva Titave | B12: 1 | D12: =VLOOKUP(A12,'Student Master'!H:AB,8,0) -> #N/A | E12: =VLOOKUP(A12,'Student Master'!H:AB,9,0) -> #N/A | F12: =VLOOKUP(A12,'Student Master'!H:AB,17,0) -> #N/A | G12: =$F$2-D12 -> #N/A | H12: 6 | K12: 0
A13: Bhavya | B13: 1 | D13: =VLOOKUP(A13,'Student Master'!H:AB,8,0) -> #N/A | E13: =VLOOKUP(A13,'Student Master'!H:AB,9,0) -> #N/A | F13: =VLOOKUP(A13,'Student Master'!H:AB,17,0) -> #N/A | G13: =$F$2-D13 -> #N/A | H13: 6 | K13: 0
A14: Chaitnya Bhave | B14: 1 | C14: 3600 | D14: =VLOOKUP(A14,'Student Master'!H:AB,8,0) -> #N/A | E14: =VLOOKUP(A14,'Student Master'!H:AB,9,0) -> #N/A | F14: =VLOOKUP(A14,'Student Master'!H:AB,17,0) -> #N/A | G14: =$F$2-D14 -> #N/A | H14: 6 | K14: 0
A15: Hazel Lalvani | B15: 1 | D15: =VLOOKUP(A15,'Student Master'!H:AB,8,0) -> #N/A | E15: =VLOOKUP(A15,'Student Master'!H:AB,9,0) -> #N/A | F15: =VLOOKUP(A15,'Student Master'!H:AB,17,0) -> #N/A | G15: =$F$2-D15 -> #N/A | H15: 6 | K15: 0
A16: Hitansh Agarwal | B16: 1 | D16: =VLOOKUP(A16,'Student Master'!H:AB,8,0) -> #N/A | E16: =VLOOKUP(A16,'Student Master'!H:AB,9,0) -> #N/A | F16: =VLOOKUP(A16,'Student Master'!H:AB,17,0) -> #N/A | G16: =$F$2-D16 -> #N/A | H16: 6 | K16: 0
A17: Hitanshi Agarwal | B17: 1 | D17: =VLOOKUP(A17,'Student Master'!H:AB,8,0) -> #N/A | E17: =VLOOKUP(A17,'Student Master'!H:AB,9,0) -> #N/A | F17: =VLOOKUP(A17,'Student Master'!H:AB,17,0) -> #N/A | G17: =$F$2-D17 -> #N/A | H17: 6 | K17: 0
A18: Hridhaan Bagla | B18: 1 | C18: 4800 | D18: =VLOOKUP(A18,'Student Master'!H:AB,8,0) -> #N/A | E18: =VLOOKUP(A18,'Student Master'!H:AB,9,0) -> #N/A | F18: =VLOOKUP(A18,'Student Master'!H:AB,17,0) -> #N/A | G18: =$F$2-D18 -> #N/A | H18: 6 | K18: 0
A19: Jyotiraditya Jagtap | B19: 1 | D19: =VLOOKUP(A19,'Student Master'!H:AB,8,0) -> #N/A | E19: =VLOOKUP(A19,'Student Master'!H:AB,9,0) -> #N/A | F19: =VLOOKUP(A19,'Student Master'!H:AB,17,0) -> #N/A | G19: =$F$2-D19 -> #N/A | H19: 6 | K19: 0
A20: Mahir Gandhi | B20: 1 | C20: 3600 | D20: =VLOOKUP(A20,'Student Master'!H:AB,8,0) -> #N/A | E20: =VLOOKUP(A20,'Student Master'!H:AB,9,0) -> #N/A | F20: =VLOOKUP(A20,'Student Master'!H:AB,17,0) -> #N/A | G20: =$F$2-D20 -> #N/A | H20: 6 | K20: 0
A21: Manan Mulchandani | B21: 1 | C21: 1600 | D21: =VLOOKUP(A21,'Student Master'!H:AB,8,0) -> #N/A | E21: =VLOOKUP(A21,'Student Master'!H:AB,9,0) -> #N/A | F21: =VLOOKUP(A21,'Student Master'!H:AB,17,0) -> #N/A | G21: =$F$2-D21 -> #N/A | H21: 6 | K21: 0
A22: Mayank Agarwal | B22: 1 | C22: 3600 | D22: =VLOOKUP(A22,'Student Master'!H:AB,8,0) -> #N/A | E22: =VLOOKUP(A22,'Student Master'!H:AB,9,0) -> #N/A | F22: =VLOOKUP(A22,'Student Master'!H:AB,17,0) -> #N/A | G22: =$F$2-D22 -> #N/A | H22: 6 | K22: 0
A23: Navya Thakkar | B23: 1 | C23: 4800 | D23: =VLOOKUP(A23,'Student Master'!H:AB,8,0) -> #N/A | E23: =VLOOKUP(A23,'Student Master'!H:AB,9,0) -> #N/A | F23: =VLOOKUP(A23,'Student Master'!H:AB,17,0) -> #N/A | G23: =$F$2-D23 -> #N/A | H23: 6 | K23: 0
A24: Paridhi Agarwal | B24: 1 | C24: 2400 | D24: =VLOOKUP(A24,'Student Master'!H:AB,8,0) -> #N/A | E24: =VLOOKUP(A24,'Student Master'!H:AB,9,0) -> #N/A | F24: =VLOOKUP(A24,'Student Master'!H:AB,17,0) -> #N/A | G24: =$F$2-D24 -> #N/A | H24: 6 | K24: 0
A25: Prathmesh Zope | B25: 1 | C25: 3600 | D25: =VLOOKUP(A25,'Student Master'!H:AB,8,0) -> #N/A | E25: =VLOOKUP(A25,'Student Master'!H:AB,9,0) -> #N/A | F25: =VLOOKUP(A25,'Student Master'!H:AB,17,0) -> #N/A | G25: =$F$2-D25 -> #N/A | H25: 6 | K25: 0
A26: Riyansh Pawar | B26: 1 | D26: =VLOOKUP(A26,'Student Master'!H:AB,8,0) -> #N/A | E26: =VLOOKUP(A26,'Student Master'!H:AB,9,0) -> #N/A | F26: =VLOOKUP(A26,'Student Master'!H:AB,17,0) -> #N/A | G26: =$F$2-D26 -> #N/A | K26: 1200
A27: Samyak Bora | B27: 1 | D27: =VLOOKUP(A27,'Student Master'!H:AB,8,0) -> #N/A | E27: =VLOOKUP(A27,'Student Master'!H:AB,9,0) -> #N/A | F27: =VLOOKUP(A27,'Student Master'!H:AB,17,0) -> #N/A | G27: =$F$2-D27 -> #N/A | K27: 1200
A28: Shaurya Sachin Atkare | B28: 1 | D28: =VLOOKUP(A28,'Student Master'!H:AB,8,0) -> #N/A | E28: =VLOOKUP(A28,'Student Master'!H:AB,9,0) -> #N/A | F28: =VLOOKUP(A28,'Student Master'!H:AB,17,0) -> #N/A | G28: =$F$2-D28 -> #N/A | K28: 1200
A29: Shreshth Gupta | B29: 1 | C29: 3600 | D29: =VLOOKUP(A29,'Student Master'!H:AB,8,0) -> #N/A | E29: =VLOOKUP(A29,'Student Master'!H:AB,9,0) -> #N/A | F29: =VLOOKUP(A29,'Student Master'!H:AB,17,0) -> #N/A | G29: =$F$2-D29 -> #N/A | K29: 1200
A30: Shresth Deb | B30: 1 | C30: 3600 | D30: =VLOOKUP(A30,'Student Master'!H:AB,8,0) -> #N/A | E30: =VLOOKUP(A30,'Student Master'!H:AB,9,0) -> #N/A | F30: =VLOOKUP(A30,'Student Master'!H:AB,17,0) -> #N/A | G30: =$F$2-D30 -> #N/A | K30: 1200
A31: Shreya Asarma | B31: 1 | C31: 3600 | D31: =VLOOKUP(A31,'Student Master'!H:AB,8,0) -> #N/A | E31: =VLOOKUP(A31,'Student Master'!H:AB,9,0) -> #N/A | F31: =VLOOKUP(A31,'Student Master'!H:AB,17,0) -> #N/A | G31: =$F$2-D31 -> #N/A | K31: 1200
A32: Shridnyesh Aher | B32: 1 | C32: 3600 | D32: =VLOOKUP(A32,'Student Master'!H:AB,8,0) -> #N/A | E32: =VLOOKUP(A32,'Student Master'!H:AB,9,0) -> #N/A | F32: =VLOOKUP(A32,'Student Master'!H:AB,17,0) -> #N/A | G32: =$F$2-D32 -> #N/A | K32: 1200
A33: Spruha Patil | B33: 1 | C33: 1800 | D33: =VLOOKUP(A33,'Student Master'!H:AB,8,0) -> #N/A | E33: =VLOOKUP(A33,'Student Master'!H:AB,9,0) -> #N/A | F33: =VLOOKUP(A33,'Student Master'!H:AB,17,0) -> #N/A | G33: =$F$2-D33 -> #N/A | K33: 1200
A34: Tanish Mulay | B34: 1 | D34: =VLOOKUP(A34,'Student Master'!H:AB,8,0) -> #N/A | E34: =VLOOKUP(A34,'Student Master'!H:AB,9,0) -> #N/A | F34: =VLOOKUP(A34,'Student Master'!H:AB,17,0) -> #N/A | G34: =$F$2-D34 -> #N/A | K34: 1200
A35: Tanush Mulay | B35: 1 | C35: 3250 | D35: =VLOOKUP(A35,'Student Master'!H:AB,8,0) -> #N/A | E35: =VLOOKUP(A35,'Student Master'!H:AB,9,0) -> #N/A | F35: =VLOOKUP(A35,'Student Master'!H:AB,17,0) -> #N/A | G35: =$F$2-D35 -> #N/A | K35: 1200
A36: Vedant Kumar | B36: 1 | C36: 15600 | D36: =VLOOKUP(A36,'Student Master'!H:AB,8,0) -> #N/A | E36: =VLOOKUP(A36,'Student Master'!H:AB,9,0) -> #N/A | F36: =VLOOKUP(A36,'Student Master'!H:AB,17,0) -> #N/A | G36: =$F$2-D36 -> #N/A | K36: 1200
A37: Vikramaditya Jagtap | B37: 1 | D37: =VLOOKUP(A37,'Student Master'!H:AB,8,0) -> #N/A | E37: =VLOOKUP(A37,'Student Master'!H:AB,9,0) -> #N/A | F37: =VLOOKUP(A37,'Student Master'!H:AB,17,0) -> #N/A | G37: =$F$2-D37 -> #N/A | K37: 1200
A38: Viraj Sethi | B38: 1 | C38: 2400 | D38: =VLOOKUP(A38,'Student Master'!H:AB,8,0) -> #N/A | E38: =VLOOKUP(A38,'Student Master'!H:AB,9,0) -> #N/A | F38: =VLOOKUP(A38,'Student Master'!H:AB,17,0) -> #N/A | G38: =$F$2-D38 -> #N/A | K38: 2500
A39: Vivaan Dabe | B39: 1 | C39: 3600 | D39: =VLOOKUP(A39,'Student Master'!H:AB,8,0) -> #N/A | E39: =VLOOKUP(A39,'Student Master'!H:AB,9,0) -> #N/A | F39: =VLOOKUP(A39,'Student Master'!H:AB,17,0) -> #N/A | G39: =$F$2-D39 -> #N/A | K39: 2500
A40: Vivaan Garg | B40: 1 | D40: =VLOOKUP(A40,'Student Master'!H:AB,8,0) -> #N/A | E40: =VLOOKUP(A40,'Student Master'!H:AB,9,0) -> #N/A | F40: =VLOOKUP(A40,'Student Master'!H:AB,17,0) -> #N/A | G40: =$F$2-D40 -> #N/A | K40: 2500
A41: Yugansh Pawar | B41: 1 | D41: =VLOOKUP(A41,'Student Master'!H:AB,8,0) -> #N/A | E41: =VLOOKUP(A41,'Student Master'!H:AB,9,0) -> #N/A | F41: =VLOOKUP(A41,'Student Master'!H:AB,17,0) -> #N/A | G41: =$F$2-D41 -> #N/A | K41: 2500
...

Sheet D0
A3: Sum of Received Fee | C3: Level Progress
A4: Student Name | B4: Level Name | C4: Completed | D4: Completed | E4: WIP | F4: WIP_InActive | G4: Grand Total
A5: Shresth Deb | B5: Runner 5 | E5: 3600 | G5: 3600
B6: Runner-1 | C6: 4800 | G6: 4800
B7: Runner-2 | C7: 3600 | G7: 3600
B8: Runner-3 | C8: 4800 | G8: 4800
B9: Runner-4 | C9: 5400 | G9: 5400
A10: Shresth Deb Total | C10: 18600 | E10: 3600 | G10: 22200
A11: Shreshth Gupta | B11: Runner-1 | D11: 7200 | G11: 7200
B12: Runner-2 | C12: 6300 | G12: 6300
B13: Runner-3 | E13: 3600 | G13: 3600
B14: Sr.KG | C14: 4800 | G14: 4800
A15: Shreshth Gupta Total | C15: 11100 | D15: 7200 | E15: 3600 | G15: 21900
A16: Riyansh Pawar | B16: Runner 5 | C16: 3600 | G16: 3600
B17: Runner-1 | C17: 3600 | G17: 3600
B18: Runner-2 | C18: 3600 | G18: 3600
B19: Runner-3 | C19: 3600 | G19: 3600
B20: Runner-4 | C20: 3600 | G20: 3600
B21: Advance level -1 | C21: 3600 | G21: 3600
B22: Advance level -2
A23: Riyansh Pawar Total | C23: 21600 | G23: 21600
A24: Prathmesh Zope | B24: Advance Level-1 | C24: 3600 | G24: 3600
B25: Sprinter Level-1 | C25: 3600 | G25: 3600
B26: Sprinter Level-2 | C26: 3600 | G26: 3600
B27: Sprinter Level-3 | C27: 3600 | G27: 3600
B28: Sprinter Level-4 | C28: 3600 | G28: 3600
B29: Advance Level-2 | E29: 3600 | G29: 3600
A30: Prathmesh Zope Total | C30: 18000 | E30: 3600 | G30: 21600
A31: Chaitnya Bhave | B31: Runner-1 | C31: 7800 | G31: 7800
B32: Runner-2 | C32: 7200 | G32: 7200
B33: Runner-3 | E33: 3600 | G33: 3600
A34: Chaitnya Bhave Total | C34: 15000 | E34: 3600 | G34: 18600
A35: Shubhra Rokade | B35: Sprinter Level-1 | C35: 3600 | G35: 3600
B36: Sprinter Level-2 | C36: 3000 | G36: 3000
B37: Sprinter Level-3 | C37: 3000 | G37: 3000
B38: Sprinter Level-4 | D38: 3600 | G38: 3600
B39: Advance level -1 | C39: 4200 | G39: 4200
A40: Shubhra Rokade Total | C40: 13800 | D40: 3600 | G40: 17400
A41: Aarohi Fegde | B41: Runner-1 | C41: 4800 | G41: 4800
B42: Runner-2 | C42: 2400 | G42: 2400
...

Sheet D1
B1: Level Progress | C1: WIP | K1: =K15*1200 -> 8400
B3: Count of Student Name | C3: Batch | O3: Time Slot | P3: Day wise calendar block
B4: Level # | C4: Daily-4-5 | D4: M-W-4-5 | E4: M-F-7-8 | F4: O-T-T-4-5 | G4: T-T-6-7 | H4: W-F-6-7 | I4: SAT-4-6 | J4: (blank) | K4: Sun 4-6 | L4: Daily | M4: Grand Total | P4: MON | Q4: TUE | R4: WED | S4: THU | T4: FRI | U4: SAT | V4: SUN | W4: Total | X4: PerMonth
B5: A01 | K5: 1 | M5: 1 | O5: 4 TO 5 | P5: 1 | Q5: 1 | R5: 1 | S5: 1 | U5: 1 | V5: 1 | W5: 6
B6: A02 | C6: 2 | G6: 1 | H6: 3 | M6: 6 | O6: 5 TO 6 | U6: 1 | V6: 1 | W6: 2
B7: A03 | D7: 3 | E7: 2 | G7: 4 | H7: 2 | I7: 1 | J7: 1 | K7: 4 | L7: 1 | M7: 18 | O7: 6 TO 7 | Q7: 1 | R7: 1 | S7: 1 | T7: 1 | W7: 4
B8: A04 | D8: 1 | E8: 1 | I8: 1 | J8: 1 | K8: 1 | M8: 5 | O8: 7 TO 8 | P8: 1 | T8: 1 | W8: 2
B9: A05 | D9: 1 | F9: 1 | I9: 1 | M9: 3 | O9: Total Hrs | P9: 2 | Q9: 2 | R9: 2 | S9: 2 | T9: 2 | U9: 2 | V9: 2 | W9: 14 | X9: 60 | Y9: =X9/9 -> 6.6666667
B10: A06 | D10: 2 | G10: 1 | K10: 1 | M10: 4
B11: A07 | F11: 1 | M11: 1 | O11: Time Slot | P11: Day and Batch wise student count
B12: A08 | D12: 1 | M12: 1 | P12: MON | Q12: TUE | R12: WED | S12: THU | T12: FRI | U12: SAT | V12: SUN
B13: A11 | E13: 1 | M13: 1 | O13: 4 TO 5 | P13: =2+6 -> 8 | Q13: =2+2 -> 4 | R13: =2+6 -> 8 | S13: =2+2 -> 4 | U13: =2+8 -> 10 | V13: 0
B14: A13 | E14: 1 | M14: 1 | O14: 5 TO 6 | U14: 8 | V14: 1
B15: Grand Total | C15: 2 | D15: 8 | E15: 5 | F15: 2 | G15: 6 | H15: 5 | I15: 3 | J15: 2 | K15: 7 | L15: 1 | M15: 41 | O15: 6 TO 7 | Q15: 4 | R15: 6 | S15: 4 | T15: 8
O16: 7 TO 8 | P16: 6 | T16: 6
O17: Total# | P17: 14 | Q17: 8 | R17: 14 | S17: 8 | T17: 14 | U17: 10 | V17: 1

Sheet D2
B1: Level Progress | C1: WIP
B3: Count of Student Name | D3: Level #
B4: Batch | C4: Student Name | D4: A01 | E4: A02 | F4: A03 | G4: A04 | H4: A05 | I4: A06 | J4: A07 | K4: A08 | L4: A11 | M4: A13 | N4: Grand Total
B5: Daily-4-5 | C5: Prisha Deshmukh | E5: 1 | N5: 1
C6: Riaan Deshmukh | E6: 1 | N6: 1
B7: Daily-4-5 Total | E7: 2 | N7: 2
B8: M-F-7-8 | C8: Arnav Sachin Patil | G8: 1 | N8: 1
C9: Arnish Jhamtani | F9: 1 | N9: 1
C10: Prathmesh Zope | M10: 1 | N10: 1
C11: Shubhra Rokade | L11: 1 | N11: 1
C12: Vedant Kumar | F12: 1 | N12: 1
B13: M-F-7-8 Total | F13: 2 | G13: 1 | L13: 1 | M13: 1 | N13: 5
B14: M-W-4-5 | C14: Aaradhya | K14: 1 | N14: 1
C15: Aayushman Kale | I15: 1 | N15: 1
C16: Advik Khadelwal | F16: 1 | N16: 1
C17: Jyotiraditya Jagtap | I17: 1 | N17: 1
C18: Mahir Gandhi | G18: 1 | N18: 1
C19: Vikramaditya Jagtap | H19: 1 | N19: 1
C20: Kabir Kherajani | F20: 1 | N20: 1
C21: Nivaan Keswani | F21: 1 | N21: 1
B22: M-W-4-5 Total | F22: 3 | G22: 1 | H22: 1 | I22: 2 | K22: 1 | N22: 8
B23: O-T-T-4-5 | C23: Riyansh Pawar | J23: 1 | N23: 1
C24: Shreya Asarma | H24: 1 | N24: 1
B25: O-T-T-4-5 Total | H25: 1 | J25: 1 | N25: 2
B26: SAT-4-6 | C26: Atharva Titave | H26: 1 | N26: 1
C27: Shridnyesh Aher | F27: 1 | N27: 1
C28: Spruha Patil | G28: 1 | N28: 1
B29: SAT-4-6 Total | F29: 1 | G29: 1 | H29: 1 | N29: 3
B30: T-T-6-7 | C30: Aarohi Fegde | I30: 1 | N30: 1
C31: Archit Shette | F31: 1 | N31: 1
C32: Navya Thakkar | F32: 1 | N32: 1
C33: Paridhi Agarwal | E33: 1 | N33: 1
C34: Tanvi Naik | F34: 1 | N34: 1
C35: Satvika Yadav | F35: 1 | N35: 1
B36: T-T-6-7 Total | E36: 1 | F36: 4 | I36: 1 | N36: 6
B37: W-F-6-7 | C37: Divisha Vyawahare | F37: 1 | N37: 1
C38: Hridhaan Bagla | E38: 1 | N38: 1
C39: Ishanvi Bhatt | F39: 1 | N39: 1
C40: Prisha Shah | E40: 1 | N40: 1
C41: Yugansh Pawar | E41: 1 | N41: 1
...

Sheet D4
A3: Student Name | B3: Level Name | C3: Sum of Expected Fee | D3: Sum of Received Fee | E3: Sum of NO OF SESSIONS TAKEN | F3: Sum of MONTHS TAken to complete levvel
A4: Shresth Deb | B4: Runner 5 | C4: 3600 | D4: 3600 | H4: =F4*1200 -> 0 | I4: =D4-H4 -> 3600
B5: Runner-1 | C5: 4800 | D5: 4800 | E5: 29 | F5: 3.6 | H5: =F5*1200 -> 4320 | I5: =D5-H5 -> 480
B6: Runner-2 | C6: 3600 | D6: 3600 | E6: 21 | F6: 2.5333333 | H6: =F6*1200 -> 3040 | I6: =D6-H6 -> 560
B7: Runner-3 | C7: 4800 | D7: 4800 | E7: 33 | F7: 4.0666667 | H7: 5400 | I7: 0
B8: Runner-4 | C8: 5400 | D8: 5400 | E8: 128 | F8: 15.966667
A9: Shresth Deb Total | C9: 22200 | D9: 22200 | E9: 211 | F9: 26.166667 | H9: =F9*1200 -> 31400 | I9: =D9-H9 -> -9200
A10: Shreshth Gupta | B10: Runner-1 | C10: 6000 | D10: 7200 | E10: 59 | F10: 7.2666667 | H10: =F10*1200 -> 8720 | I10: =D10-H10 -> -1520
B11: Runner-2 | C11: 3600 | D11: 6300 | E11: 42 | F11: 5.1333333 | H11: =F11*1200 -> 6160 | I11: =D11-H11 -> 140
B12: Runner-3 | C12: 3600 | D12: 3600 | H12: =F12*1200 -> 0 | I12: =D12-H12 -> 3600
B13: Sr.KG | C13: 4800 | D13: 4800 | E13: 30 | F13: 3.6666667 | H13: =F13*1200 -> 4400 | I13: =D13-H13 -> 400
A14: Shreshth Gupta Total | C14: 18000 | D14: 21900 | E14: 131 | F14: 16.066667 | H14: =F14*1200 -> 19280 | I14: =D14-H14 -> 2620
A15: Riyansh Pawar | B15: Runner 5 | C15: 3600 | D15: 3600 | E15: 25 | F15: 3.0666667 | H15: =F15*1200 -> 3680 | I15: =D15-H15 -> -80
B16: Runner-1 | C16: 3600 | D16: 3600 | E16: 11 | F16: 1.3666667 | H16: =F16*1200 -> 1640 | I16: =D16-H16 -> 1960
B17: Runner-2 | C17: 3600 | D17: 3600 | E17: 9 | F17: 1.1 | H17: =F17*1200 -> 1320 | I17: =D17-H17 -> 2280
B18: Runner-3 | C18: 3600 | D18: 3600 | E18: 17 | F18: 2.1 | H18: =F18*1200 -> 2520 | I18: =D18-H18 -> 1080
B19: Runner-4 | C19: 3600 | D19: 3600 | E19: 14 | F19: 1.6333333 | H19: =F19*1200 -> 1960 | I19: =D19-H19 -> 1640
B20: Advance level -1 | C20: 3600 | D20: 3600 | H20: =F20*1200 -> 0 | I20: =D20-H20 -> 3600
B21: Advance level -2 | C21: 3600 | H21: =F21*1200 -> 0 | I21: =D21-H21 -> 0
A22: Riyansh Pawar Total | C22: 25200 | D22: 21600 | E22: 76 | F22: 9.2666667 | H22: =F22*1200 -> 11120 | I22: =D22-H22 -> 10480
A23: Prathmesh Zope | B23: Advance Level-1 | C23: 3600 | D23: 3600 | E23: 50 | F23: 6.1666667 | H23: =F23*1200 -> 7400 | I23: =D23-H23 -> -3800
B24: Sprinter Level-1 | C24: 3600 | D24: 3600 | E24: 44 | F24: 5.4666667 | H24: =F24*1200 -> 6560 | I24: =D24-H24 -> -2960
B25: Sprinter Level-2 | C25: 3600 | D25: 3600 | E25: 24 | F25: 2.9 | H25: =F25*1200 -> 3480 | I25: =D25-H25 -> 120
B26: Sprinter Level-3 | C26: 3600 | D26: 3600 | E26: 40 | F26: 4.9 | H26: =F26*1200 -> 5880 | I26: =D26-H26 -> -2280
B27: Sprinter Level-4 | C27: 3600 | D27: 3600 | E27: 46 | F27: 5.6333333 | H27: =F27*1200 -> 6760 | I27: =D27-H27 -> -3160
B28: Advance Level-2 | C28: 3600 | D28: 3600 | E28: 83 | F28: 10.333333 | H28: =F28*1200 -> 12400 | I28: =D28-H28 -> -8800
A29: Prathmesh Zope Total | C29: 21600 | D29: 21600 | E29: 287 | F29: 35.4 | H29: =F29*1200 -> 42480 | I29: =D29-H29 -> -20880
A30: Chaitnya Bhave | B30: Runner-1 | C30: 8400 | D30: 7800 | E30: 58 | F30: 7.1333333 | H30: =F30*1200 -> 8560 | I30: =D30-H30 -> -760
B31: Runner-2 | C31: 3600 | D31: 7200 | E31: 68 | F31: 8.4 | H31: =F31*1200 -> 10080 | I31: =D31-H31 -> -2880
B32: Runner-3 | C32: 3600 | D32: 3600 | H32: =F32*1200 -> 0 | I32: =D32-H32 -> 3600
A33: Chaitnya Bhave Total | C33: 15600 | D33: 18600 | E33: 126 | F33: 15.533333 | H33: =F33*1200 -> 18640 | I33: =D33-H33 -> -40
A34: Shubhra Rokade | B34: Sprinter Level-1 | C34: 3600 | D34: 3600 | E34: 10 | F34: 1.2 | H34: =F34*1200 -> 1440 | I34: =D34-H34 -> 2160
B35: Sprinter Level-2 | C35: 3600 | D35: 3000 | E35: 8 | F35: 0.93333333 | H35: =F35*1200 -> 1120 | I35: =D35-H35 -> 1880
B36: Sprinter Level-3 | C36: 3600 | D36: 3000 | E36: 19 | F36: 2.2666667 | H36: =F36*1200 -> 2720 | I36: =D36-H36 -> 280
B37: Sprinter Level-4 | C37: 3600 | D37: 3600 | E37: 33 | F37: 4.0666667 | H37: =F37*1200 -> 4880 | I37: =D37-H37 -> -1280
B38: Advance level -1 | C38: 3600 | D38: 4200 | E38: 45 | F38: 5.6 | H38: =F38*1200 -> 6720 | I38: =D38-H38 -> -2520
A39: Shubhra Rokade Total | C39: 18000 | D39: 17400 | E39: 115 | F39: 14.066667 | H39: =F39*1200 -> 16880 | I39: =D39-H39 -> 520
A40: Aarohi Fegde | B40: Runner-1 | C40: 4800 | D40: 4800 | E40: 37 | F40: 4.5333333 | H40: =F40*1200 -> 5440 | I40: =D40-H40 -> -640
B41: Runner-2 | C41: 2400 | D41: 2400 | E41: 19 | F41: 2.3 | H41: =F41*1200 -> 2760 | I41: =D41-H41 -> -360
B42: Runner-3 | C42: 3600 | D42: 3600 | E42: 24 | F42: 2.9666667 | H42: =F42*1200 -> 3560 | I42: =D42-H42 -> 40
...

Sheet D3
B1: Level Progress | C1: WIP
B3: Count of Student Name | D3: Batch
B4: Level # | C4: Student Name | D4: Daily-4-5 | E4: M-F-7-8 | F4: M-W-4-5 | G4: O-T-T-4-5 | H4: SAT-4-6 | I4: T-T-6-7 | J4: W-F-6-7 | K4: (blank) | L4: Sun 4-6 | M4: Daily | N4: Grand Total
B5: A01 | C5: Rumi Pandita | L5: 1 | N5: 1
B6: A01 Total | L6: 1 | N6: 1
B7: A02 | C7: Hridhaan Bagla | J7: 1 | N7: 1
C8: Paridhi Agarwal | I8: 1 | N8: 1
C9: Prisha Deshmukh | D9: 1 | N9: 1
C10: Prisha Shah | J10: 1 | N10: 1
C11: Riaan Deshmukh | D11: 1 | N11: 1
C12: Yugansh Pawar | J12: 1 | N12: 1
B13: A02 Total | D13: 2 | I13: 1 | J13: 3 | N13: 6
B14: A03 | C14: Advik Khadelwal | F14: 1 | N14: 1
C15: Archit Shette | I15: 1 | N15: 1
C16: Arnav Pol | L16: 1 | N16: 1
C17: Arnish Jhamtani | E17: 1 | N17: 1
C18: Avyaan Chaumal | K18: 1 | N18: 1
C19: Divisha Vyawahare | J19: 1 | N19: 1
C20: Ishanvi Bhatt | J20: 1 | N20: 1
C21: Jaanvi Nitin Khandagale | L21: 1 | N21: 1
C22: Navya Thakkar | I22: 1 | N22: 1
C23: Shridnyesh Aher | H23: 1 | N23: 1
C24: Tanvi Naik | I24: 1 | N24: 1
C25: Vedant Kumar | E25: 1 | N25: 1
C26: Vivaan Garg | L26: 1 | N26: 1
C27: Kaira Sharma | L27: 1 | N27: 1
C28: Kabir Kherajani | F28: 1 | N28: 1
C29: Nivaan Keswani | F29: 1 | N29: 1
C30: Samyak Bora | M30: 1 | N30: 1
C31: Satvika Yadav | I31: 1 | N31: 1
B32: A03 Total | E32: 2 | F32: 3 | H32: 1 | I32: 4 | J32: 2 | K32: 1 | L32: 4 | M32: 1 | N32: 18
B33: A04 | C33: Arnav Sachin Patil | E33: 1 | N33: 1
C34: Chaitnya Bhave | L34: 1 | N34: 1
C35: Mahir Gandhi | F35: 1 | N35: 1
C36: Shreshth Gupta | K36: 1 | N36: 1
C37: Spruha Patil | H37: 1 | N37: 1
B38: A04 Total | E38: 1 | F38: 1 | H38: 1 | K38: 1 | L38: 1 | N38: 5
B39: A05 | C39: Atharva Titave | H39: 1 | N39: 1
C40: Shreya Asarma | G40: 1 | N40: 1
C41: Vikramaditya Jagtap | F41: 1 | N41: 1
...

Sheet Trophy Nomination-Distribution
D1: TROPHY Nomination and Distribution
A3: Sr.No. | B3: Trohpy Season | C3: Name | D3: Level | E3: % | F3: Nominated | G3: Distributed on
A4: 1 | B4: 2nd | C4: Jyotiraditya Nagnath Jagtap | D4: Runner 2 | E4: 100 | F4: Yes | G4: Yes
A5: 2 | B5: 2nd | C5: Aara Y. | D5: Sprinter 1 | E5: 100 | F5: Yes | G5: Yes
A6: 3 | B6: 2nd | C6: Yashwi Atulkumar Patil | D6: Sr.Kg. | E6: 96 | F6: Yes | G6: Yes
A7: 4 | B7: 2nd | C7: Shreya Asarma | D7: Runner 1 | E7: 95 | F7: Yes | G7: Yes
A8: 5 | B8: 2nd | C8: Shubhra Rokade | D8: Sprinter 2 | E8: 100 | F8: Yes | G8: Yes
A9: 6 | B9: 2nd | C9: Spruha Sagar Patil | D9: Runner 1 | E9: 95 | F9: Yes | G9: Yes
A10: 7 | B10: 2nd | C10: Arnav Sachin Patil | D10: Runner 1 | E10: 93 | F10: Yes | G10: Yes
A11: 8 | B11: 2nd | C11: Chaitanya Bhave | D11: Runner 1 | E11: 95 | F11: Yes | G11: Yes
A12: 9 | B12: 2nd | C12: Digvi Swapnil Nikhumbh | D12: Runner 1 | E12: 91 | F12: Yes | G12: Yes
A13: 10 | B13: 2nd | C13: Prathmesh Yogesh Zope | D13: Advance 1 | F13: Yes | G13: Pending
A14: 11 | B14: 2nd | C14: Shresth Deb | D14: Runner 4 | F14: Yes | G14: Pending
A15: 12 | B15: 2nd | C15: Arnav Nitin Patil | D15: Grand Level 1 | F15: Yes | G15: Pending
A18: 1 | B18: 3rd | C18: Avyaan Chaumal | D18: Sr.Kg | E18: 100 | F18: Yes
A19: 2 | C19: Ishanvi Bhatt | D19: Sr.kg | E19: 92 | F19: Yes
A20: 3 | C20: Navya Thakkar | D20: Sr.Kg | F20: Yes
A21: 4 | C21: Divisha Vyaware | D21: Sr.Kg | F21: Yes
A22: 5 | C22: Arnish Jhamtani | D22: Sr.Kg | E22: 100 | F22: Yes
A23: 6
A24: 7
A25: 8
A26: 9
A27: 10

Sheet TimeTable
C1: Prathamesh | D1: Atharv Titave | E1: Ishan | F1: Aarohi | G1: Shreshth Gupta | H1: Chaitanya Bhave | I1: Aayushman | J1: Swastika | K1: Vikramaditya | L1: Jyotiraditya | M1: Riyanash Pawar | N1: Shubhra | O1: Shreya | P1: Spruha | Q1: Aaradhya | R1: Prisha Shah | S1: Arnav Patil | T1: Avyaan | U1: Ishanvi | V1: Divisha | W1: Vedant | X1: Shridnyesh
C3: Monday
B4: Monday
B5: Tuesday
B6: Wednesday
B7: Thursday
B8: Friday
B9: Saturday
B10: Sunday

Sheet Smart Kid Purchse Tracking
